Workbook

Sheet Instructions
A1: Fulfilment Plus KPI Dashboard — Instructions & Reference
A2: Last updated | B2: June 2026 | Questions? Contact mike@fulfilmentplus.co.nz
A4: 1. System Overview
A5: What this workbook does | B5: Accumulates monthly KPI data for all Fulfilment Plus customers across 6 KPIs. Two HTML dashboards (customer_dashboard.html, business_dashboard.html) are generated from this file and can be opened in any browser or shared via OneDrive.
A6: Where files live | B6: All scripts and this workbook live in: C:\Users\MikeAppleton\Claude\Projects\Fulfilment Plus KPIs\
A7: The 6 KPIs | B7: 1. Dock to Stock (target 95%) — CartonCloud inbound orders 2. Order Cut Off (target 95%) — CartonCloud outbound orders 3. Stock Accuracy (target 99.5%) — manual entry from annual stock take 4. Cycle Count — manual entry 5. Order Accuracy by Unit — manual entry (no API source yet) 6. Freight DIFOT (target 95%) — Starshipit Delivery Performance CSV
A9: 2. Monthly Workflow (run on the 1st–5th of each month)
A10: Step 1 — Extract KPIs from CartonCloud | B10: Run in terminal (in the project folder): python extract_kpi_data.py YYYY-MM Replace YYYY-MM with the prior month, e.g. 2026-06 This pulls Dock to Stock and Order Cut Off for all customers and appends rows to KPI_Data.
A11: Step 2 — Extract DIFOT from Starshipit | B11: a) In Starshipit: Reports → Generate Report → Delivery Performance Set date range to the full prior month. Download the .xlsx file. b) Copy the file into the project folder, then run: python extract_difot.py YYYY-MM DeliveryPerformanceReport_....xlsx This matches each shipment to a customer via CartonCloud and appends DIFOT rows.
A12: Step 3 — Add manual KPIs | B12: For Stock Accuracy, Cycle Count, Order Accuracy: add rows directly to the KPI_Data tab. Columns: Month | Customer | KPI | Carrier (blank) | Target | Num | Den Columns H, I, J use formulas — copy down from an existing row.
A13: Step 4 — Regenerate dashboards | B13: Run: python generate_dashboards.py This rewrites customer_dashboard.html and business_dashboard.html.
A15: 3. Scheduled (Automatic) Tasks
A16: mtd-dashboard-refresh | B16: Runs daily at 7:00 AM. Executes mtd_kpis.py (fetches this month's CartonCloud orders and computes month-to-date Dock to Stock and Order Cut Off) then regenerates both dashboards. MTD badges appear on the dashboards under each KPI card.
A17: awaiting-stock-snapshot | B17: Runs daily at 6:10 PM. Records which CartonCloud outbound orders are in AWAITING_STOCK status and when they transition off (stock becomes available). Used in future to adjust the Order Cut Off clock for orders that were held waiting on stock.
A18: monthly-kpi-extraction | B18: Runs on the 5th of each month at 8:00 AM. Automatically runs extract_kpi_data.py for the prior month. You still need to manually run extract_difot.py and add any manual KPIs.
A20: 4. KPI Calculation Rules
A21: Dock to Stock | B21: Inbound orders verified within 48 hours of arrivalDate. Orders still within their 48-hr window (MTD only) are excluded from the denominator.
A22: Order Cut Off — standard rule | B22: Orders received before 2:00 PM NZ time on a weekday must dispatch same day. Orders received after 2:00 PM or on a weekend must dispatch by 2:00 PM next business day.
A23: Order Cut Off — requiredDate rule | B23: If an order has a requiredDate set, an alternative deadline is calculated as 2 business days before requiredDate at 2:00 PM NZ. Final deadline = max(standard, requiredDate-based). This only ever makes the deadline MORE lenient, never stricter.
A24: Order Cut Off — Exceptions tab | B24: Three override tables in the Exceptions tab (see below): • Customer Cutoff Time Overrides — change the 2pm cutoff and/or rule for a customer • Order-Level Exceptions — exclude or force-count a specific order • Order Content-Based Overrides — override deadline based on order content (e.g. Farmers stores)
A25: Freight DIFOT | B25: NZ North Island (postcode < 7000): delivered within 1 business day of carrier pickup. NZ South Island (postcode ≥ 7000): delivered within 3 business days of carrier pickup. Rural: +2 business days. DG (dangerous goods): +2 business days. International shipments excluded. Only CartonCloud-sourced Starshipit orders counted. ⚠ Known gap: Rural flag and DG flag do not currently appear in the Starshipit export (all rows show Rural=No, no DG codes present). Raise with Starshipit support.
A27: 5. How to Add Exceptions
A28: Customer Cutoff Override | B28: Exceptions tab → Table 1 'Customer Cutoff Time Overrides' Add a row: Customer | Cutoff Time (HH:MM) | Deadline Rule | Effective From | Effective To | Reason Deadline Rule options: 'Same day' or 'Next business day (EOD)' Leave Effective To blank for open-ended. Override only ever makes deadline MORE lenient.
A29: Order-Level Exception | B29: Exceptions tab → Table 2 'Order-Level Exceptions' Add a row: Date Logged | Customer | Order Reference | Month (YYYY-MM) | KPI | Action | Reason Action options: 'Exclude from calculation' or 'Count as met'
A30: Content-Based Override | B30: Exceptions tab → Table 3 'Order Content-Based Overrides' Add a row: Customer | Match Field | Contains | Deadline Rule | Effective From | Effective To | Reason Match Field options: 'Delivery Company Name' (checks companyName in CartonCloud delivery address) Deadline Rule: 'Same day', 'Next business day (EOD)', or 'Next Tuesday (5pm)' style Example: Vixxen | Delivery Company Name | Farmers | Next Tuesday (5pm)
A32: 6. Script Reference
A33: extract_kpi_data.py | B33: Usage: python extract_kpi_data.py YYYY-MM Pulls Dock to Stock and Order Cut Off from CartonCloud for the given month. Reads Exceptions tab. Appends rows to KPI_Data. Re-run safe (replaces existing rows for that month).
A34: extract_difot.py | B34: Usage: python extract_difot.py YYYY-MM [DeliveryPerformanceReport.xlsx] Reads Starshipit CSV, fetches CartonCloud customer map, computes Freight DIFOT, appends to KPI_Data. If no CSV path given, uses the most recently modified DeliveryPerformanceReport*.xlsx in the folder.
A35: generate_dashboards.py | B35: Usage: python generate_dashboards.py Reads kpi_dashboard.xlsx and mtd_kpis.json. Writes customer_dashboard.html and business_dashboard.html.
A36: mtd_kpis.py | B36: Usage: python mtd_kpis.py (run automatically by mtd-dashboard-refresh scheduled task) Fetches current-month CartonCloud orders, computes month-to-date Dock to Stock and Order Cut Off. Writes mtd_kpis.json. Freight DIFOT MTD not available (Starshipit API does not return full month history).
A37: daily_status_snapshot.py | B37: Usage: python daily_status_snapshot.py (run automatically by awaiting-stock-snapshot scheduled task) Logs CartonCloud AWAITING_STOCK orders to awaiting_stock_log.csv and tracks when they transition.
A39: 7. Credentials & API Access
A40: credentials.env | B40: File in the project folder containing API keys. Never share or commit this file. Keys: CARTONCLOUD_CLIENT_ID, CARTONCLOUD_CLIENT_SECRET, CARTONCLOUD_TENANT_ID STARSHIPIT_API_KEY, STARSHIPIT_SUBSCRIPTION_KEY CartonCloud: Settings → Contacts → API Clients Starshipit: Settings → API (use the parent account key)
A41: Known issue — Starshipit API | B41: The Starshipit /orders/shipped API only returns ~5 days of history regardless of date filters. Full historical data must be exported manually from the Starshipit UI (Reports → Delivery Performance). Raised with Starshipit support — update this note once resolved.
A43: 8. KPI_Data Tab Structure
A44: Column layout | B44: A: Month (date, 1st of month) | B: Customer | C: KPI name | D: Carrier (DIFOT only) E: Target (decimal, e.g. 0.95) | F: Numerator | G: Denominator H: =F/G (actual %) | I: =IF(H>=E,"Yes","No") | J: Notes (auto-filled when below target) Do not edit columns H or I — they contain formulas. Copy them from an adjacent row if adding manually.
A45: Adding a manual row | B45: 1. Go to the KPI_Data tab 2. Scroll to the next empty row after the last data row 3. Enter values in A–G and J (leave H and I blank, then copy the formulas down from the row above)

Sheet Dashboard
A1: Fulfilment Plus
A2: Monthly Customer KPI Report
A4: Customer: | C4: Aleger Studio
A5: Report Month: | C5: =Dashboard_Calc!B2
A7: KPI | B7: Target | C7: Frequency | D7: Latest Result | E7: Status | F7: Rolling 12-Month / Annual Result
A8: Dock to Stock | B8: ='KPI Schedule'!B5 | C8: ='KPI Schedule'!C5 | D8: =IF(Dashboard_Calc!E16="","No data",Dashboard_Calc!E16) | E8: =IF(ISNUMBER(D8),IF(D8>=B8,"On Target","Below Target"),"-") | F8: =IFERROR(SUM(Dashboard_Calc!C5:C16)/SUM(Dashboard_Calc!D5:D16),"No data")
A9: Stock Accuracy | B9: ='KPI Schedule'!B6 | C9: ='KPI Schedule'!C6 | D9: =IF(Dashboard_Calc!E25="","Pending",Dashboard_Calc!E25) | E9: =IF(ISNUMBER(D9),IF(D9>=B9,"On Target","Below Target"),"-") | F9: Annual KPI - see Stock Accuracy by Year table
A10: Cycle Count | B10: ='KPI Schedule'!B7 | C10: ='KPI Schedule'!C7 | D10: =IF(Dashboard_Calc!K16="","No data",Dashboard_Calc!K16) | E10: =IF(ISNUMBER(D10),IF(D10>=B10,"On Target","Below Target"),"-") | F10: =IFERROR(SUM(Dashboard_Calc!I5:I16)/SUM(Dashboard_Calc!J5:J16),"No data")
A11: Order Cut Off | B11: ='KPI Schedule'!B8 | C11: ='KPI Schedule'!C8 | D11: =IF(Dashboard_Calc!Q16="","No data",Dashboard_Calc!Q16) | E11: =IF(ISNUMBER(D11),IF(D11>=B11,"On Target","Below Target"),"-") | F11: =IFERROR(SUM(Dashboard_Calc!O5:O16)/SUM(Dashboard_Calc!P5:P16),"No data")
A12: Order Accuracy by Unit | B12: ='KPI Schedule'!B9 | C12: ='KPI Schedule'!C9 | D12: =IF(Dashboard_Calc!W16="","No data",Dashboard_Calc!W16) | E12: =IF(ISNUMBER(D12),IF(D12>=B12,"On Target","Below Target"),"-") | F12: =IFERROR(SUM(Dashboard_Calc!U5:U16)/SUM(Dashboard_Calc!V5:V16),"No data")
A13: Freight DIFOT | B13: ='KPI Schedule'!B10 | C13: ='KPI Schedule'!C10 | D13: =IF(Dashboard_Calc!AC16="","No data",Dashboard_Calc!AC16) | E13: =IF(ISNUMBER(D13),IF(D13>=B13,"On Target","Below Target"),"-") | F13: =IFERROR(SUM(Dashboard_Calc!AA5:AA16)/SUM(Dashboard_Calc!AB5:AB16),"No data")

Sheet Charts
A1: Fulfilment Plus
A2: Rolling 12-Month KPI Trends
A4: Customer: | B4: =Dashboard!C4
A5: Report Month: | B5: =Dashboard!C5

Sheet Read Me
A1: Fulfilment Plus - Customer KPI Dashboard
A2: Structure of this workbook
A4: KPI Schedule | B4: Reference tab - the official KPI targets, measures and notes (from the Fulfilment Plus KPI Schedule).
A5: Customers | B5: List of customer names. Add new customers here - they will automatically appear in the Dashboard dropdown.
A6: KPI_Data | B6: The master data table. One row per Customer / Month / KPI (and Carrier for Freight DIFOT). This is the table that should be appended to each month with results pulled from CartonCloud / Starshipit (or entered manually for Stock Accuracy / Cycle Count if those remain manual processes). Rolling 12-month and all-time history both come from this single table - just keep adding rows.
A7: Dashboard_Calc | B7: Hidden helper tab. Contains the formulas that pull the last 12 months of data for the customer selected on the Dashboard. You shouldn't need to edit this.
A8: Dashboard | B8: The customer-facing view. Pick a customer from the dropdown and the KPI summary table updates automatically.
A9: Charts | B9: Rolling 12-month trend charts (and DIFOT-by-carrier / Stock Accuracy-by-year charts) for the customer selected on the Dashboard tab.
A11: How to add a new month of data
A12: 1. Pull the relevant figures from CartonCloud (Inbound/Outbound Orders, Stock on Hand reports) and Starshipit (Tracking).
A13: 2. Add one new row to KPI_Data for each Customer x KPI (and Carrier, for Freight DIFOT) for the new month.
A14: 3. Enter the Numerator and Denominator - the Actual % and Met Target columns are formulas and will calculate automatically.
A15: 4. The Dashboard will automatically include the new month in the rolling 12-month view (it always shows the latest 12 months in the data).
A16: 5. To send a customer their report, select them on the Dashboard and export/print that sheet (or save a PDF copy).
A18: Sample data note
A19: KPI_Data currently contains illustrative SAMPLE data for two example customers (Acme Foods Ltd, BrightWear NZ) covering Jul-2024 to Jun-2026, so the dashboard and charts can be reviewed end-to-end. Replace/delete this sample data once real data is being loaded.

Sheet KPI Schedule
A1: Fulfilment Plus KPI Schedule
A2: Source: Fulfilment Plus KPI Schedule 2025
A4: KPI | B4: Target | C4: Frequency | D4: Measure | E4: Notes
A5: Dock to Stock | B5: 0.95 | C5: Monthly | D5: Shipments processed in 48hrs | E5: Measured Monthly. Max 3 shipments per day. All docs must be available before arrival.
A6: Stock Accuracy | B6: 0.995 | C6: Annual | D6: Stock Accuracy as a percentage of throughput | E6: Measured Annually based on an annual stock take. Warehouse related issues only.
A7: Cycle Count | B7: 0.995 | C7: Monthly | D7: Monthly count | E7: Measured Monthly. Counts are performed through the month.
A8: Order Cut Off | B8: 0.95 | C8: Monthly | D8: Orders in by 2pm will be ready for despatch same day | E8: Measured Monthly based on forecast and a steady order flow.
A9: Order Accuracy by Unit | B9: 0.995 | C9: Monthly | D9: Issues vs units despatched | E9: Measured Monthly. Issues need to be lodged and investigated.
A10: Freight DIFOT | B10: 0.95 | C10: Monthly | D10: Consignments delivered on time | E10: Measured Monthly based on carrier milestones. Separated by carrier.

Sheet Customers
A1: Customers
A3: Customer Name
A4: Aleger Studio
A5: Baking Tech
A6: Coromandel Mountains Company Limited
A7: Cotton Soft - Christchurch
A8: EcoPallets
A9: Flo & Frankie
A10: Geodis
A11: Gym Equip
A12: Interior Images
A13: Jock Freight - SECA
... A29: Vixxen

Sheet KPI_Data
A1: KPI_Data - master results table (append one row per Customer / Month / KPI / Carrier)
A3: Month | B3: Customer | C3: KPI | D3: Carrier | E3: Target | F3: Numerator | G3: Denominator | H3: Actual % | I3: Met Target? | J3: Notes / Action Plan
A4: 46143 | B4: Aleger Studio | C4: Dock to Stock | E4: 0.95 | F4: 1 | G4: 1 | H4: =F88/G88 | I4: =IF(H88>=E88,"Yes","No")
A5: 46143 | B5: Coromandel Mountains Company Limited | C5: Dock to Stock | E5: 0.95 | F5: 2 | G5: 3 | H5: =F89/G89 | I5: =IF(H89>=E89,"Yes","No") | J5: Below target - investigate root cause and add to next month's action plan
A6: 46143 | B6: Interior Images | C6: Dock to Stock | E6: 0.95 | F6: 2 | G6: 3 | H6: =F90/G90 | I6: =IF(H90>=E90,"Yes","No") | J6: Below target - investigate root cause and add to next month's action plan
A7: 46143 | B7: Jock Freight - SECA | C7: Dock to Stock | E7: 0.95 | F7: 3 | G7: 4 | H7: =F91/G91 | I7: =IF(H91>=E91,"Yes","No") | J7: Below target - investigate root cause and add to next month's action plan
A8: 46143 | B8: Logwin - Sikla | C8: Dock to Stock | E8: 0.95 | F8: 0 | G8: 2 | H8: =F92/G92 | I8: =IF(H92>=E92,"Yes","No") | J8: Below target - investigate root cause and add to next month's action plan
A9: 46143 | B9: Made Group NZ | C9: Dock to Stock | E9: 0.95 | F9: 0 | G9: 10 | H9: =F93/G93 | I9: =IF(H93>=E93,"Yes","No") | J9: Below target - investigate root cause and add to next month's action plan
A10: 46143 | B10: May Eleven NZ | C10: Dock to Stock | E10: 0.95 | F10: 1 | G10: 1 | H10: =F94/G94 | I10: =IF(H94>=E94,"Yes","No")
A11: 46143 | B11: Oricom | C11: Dock to Stock | E11: 0.95 | F11: 0 | G11: 1 | H11: =F11/G11 | I11: =IF(H11>=E11,"Yes","No") | J11: Below target - investigate root cause and add to next month's action plan
A12: 46143 | B12: Salt Shark | C12: Dock to Stock | E12: 0.95 | F12: 5 | G12: 5 | H12: =F95/G95 | I12: =IF(H95>=E95,"Yes","No")
A13: 46143 | B13: Stryx | C13: Dock to Stock | E13: 0.95 | F13: 1 | G13: 1 | H13: =F96/G96 | I13: =IF(H96>=E96,"Yes","No")
A14: 46143 | B14: Vixxen | C14: Dock to Stock | E14: 0.95 | F14: 3 | G14: 4 | H14: =F97/G97 | I14: =IF(H97>=E97,"Yes","No") | J14: Below target - investigate root cause and add to next month's action plan
A15: 46143 | B15: Aleger Studio | C15: Order Cut Off | E15: 0.95 | F15: 8 | G15: 8 | H15: =F98/G98 | I15: =IF(H98>=E98,"Yes","No")
A16: 46143 | B16: Coromandel Mountains Company Limited | C16: Order Cut Off | E16: 0.95 | F16: 3 | G16: 6 | H16: =F99/G99 | I16: =IF(H99>=E99,"Yes","No") | J16: Below target - investigate root cause and add to next month's action plan
A17: 46143 | B17: Interior Images | C17: Order Cut Off | E17: 0.95 | F17: 1 | G17: 2 | H17: =F100/G100 | I17: =IF(H100>=E100,"Yes","No") | J17: Below target - investigate root cause and add to next month's action plan
A18: 46143 | B18: Jock Freight - SECA | C18: Order Cut Off | E18: 0.95 | F18: 5 | G18: 12 | H18: =F101/G101 | I18: =IF(H101>=E101,"Yes","No") | J18: Below target - investigate root cause and add to next month's action plan
A19: 46143 | B19: Logwin - Sikla | C19: Order Cut Off | E19: 0.95 | F19: 2 | G19: 3 | H19: =F102/G102 | I19: =IF(H102>=E102,"Yes","No") | J19: Below target - investigate root cause and add to next month's action plan
A20: 46143 | B20: May Eleven NZ | C20: Order Cut Off | E20: 0.95 | F20: 1 | G20: 1 | H20: =F103/G103 | I20: =IF(H103>=E103,"Yes","No")
A21: 46143 | B21: Oricom | C21: Order Cut Off | E21: 0.95 | F21: 40 | G21: 51 | H21: =F104/G104 | I21: =IF(H104>=E104,"Yes","No") | J21: Below target - investigate root cause and add to next month's action plan
A22: 46143 | B22: Salt Shark | C22: Order Cut Off | E22: 0.95 | F22: 25 | G22: 79 | H22: =F105/G105 | I22: =IF(H105>=E105,"Yes","No") | J22: Below target - investigate root cause and add to next month's action plan
A23: 46143 | B23: Vixxen | C23: Order Cut Off | E23: 0.95 | F23: 235 | G23: 298 | H23: =F106/G106 | I23: =IF(H106>=E106,"Yes","No") | J23: Below target - investigate root cause and add to next month's action plan
A24: 46174 | B24: Oricom | C24: Stock Accuracy | E24: 0.995 | F24: 9994 | G24: 10000 | H24: =F24/G24 | I24: =IF(H24>=E24,"Yes","No")
A90: 46082 | B90: Coromandel Mountains Company Limited | C90: Freight DIFOT | E90: 0.95 | F90: 0 | G90: 1 | H90: =F150/G150 | I90: =IF(H150>=E150,"Yes","No") | J90: Below target - investigate root cause and add to next month's action plan
A91: 46082 | B91: Jock Freight - SECA | C91: Freight DIFOT | E91: 0.95 | F91: 9 | G91: 10 | H91: =F151/G151 | I91: =IF(H151>=E151,"Yes","No") | J91: Below target - investigate root cause and add to next month's action plan
A92: 46082 | B92: May Eleven NZ | C92: Freight DIFOT | E92: 0.95 | F92: 1 | G92: 1 | H92: =F152/G152 | I92: =IF(H152>=E152,"Yes","No")
A93: 46082 | B93: Oricom | C93: Freight DIFOT | E93: 0.95 | F93: 3 | G93: 3 | H93: =F153/G153 | I93: =IF(H153>=E153,"Yes","No")
A94: 46082 | B94: Salt Shark | C94: Freight DIFOT | E94: 0.95 | F94: 13 | G94: 18 | H94: =F154/G154 | I94: =IF(H154>=E154,"Yes","No") | J94: Below target - investigate root cause and add to next month's action plan
A95: 46113 | B95: Aleger Studio | C95: Freight DIFOT | E95: 0.95 | F95: 6 | G95: 16 | H95: =F155/G155 | I95: =IF(H155>=E155,"Yes","No") | J95: Below target - investigate root cause and add to next month's action plan
A96: 46113 | B96: Coromandel Mountains Company Limited | C96: Freight DIFOT | E96: 0.95 | F96: 4 | G96: 5 | H96: =F156/G156 | I96: =IF(H156>=E156,"Yes","No") | J96: Below target - investigate root cause and add to next month's action plan
A97: 46113 | B97: Jock Freight - SECA | C97: Freight DIFOT | E97: 0.95 | F97: 9 | G97: 10 | H97: =F157/G157 | I97: =IF(H157>=E157,"Yes","No") | J97: Below target - investigate root cause and add to next month's action plan
A98: 46113 | B98: Oricom | C98: Freight DIFOT | E98: 0.95 | F98: 22 | G98: 28 | H98: =F158/G158 | I98: =IF(H158>=E158,"Yes","No") | J98: Below target - investigate root cause and add to next month's action plan
A99: 46113 | B99: Salt Shark | C99: Freight DIFOT | E99: 0.95 | F99: 37 | G99: 45 | H99: =F159/G159 | I99: =IF(H159>=E159,"Yes","No") | J99: Below target - investigate root cause and add to next month's action plan
A100: 46143 | B100: Coromandel Mountains Company Limited | C100: Freight DIFOT | E100: 0.95 | F100: 6 | G100: 7 | H100: =F153/G153 | I100: =IF(H153>=E153,"Yes","No") | J100: Below target - investigate root cause and add to next month's action plan
A101: 46143 | B101: Interior Images | C101: Freight DIFOT | E101: 0.95 | F101: 1 | G101: 1 | H101: =F154/G154 | I101: =IF(H154>=E154,"Yes","No")
A102: 46143 | B102: Jock Freight - SECA | C102: Freight DIFOT | E102: 0.95 | F102: 5 | G102: 6 | H102: =F155/G155 | I102: =IF(H155>=E155,"Yes","No") | J102: Below target - investigate root cause and add to next month's action plan
A103: 46143 | B103: May Eleven NZ | C103: Freight DIFOT | E103: 0.95 | F103: 1 | G103: 1 | H103: =F156/G156 | I103: =IF(H156>=E156,"Yes","No")
A104: 46143 | B104: Oricom | C104: Freight DIFOT | E104: 0.95 | F104: 21 | G104: 22 | H104: =F157/G157 | I104: =IF(H157>=E157,"Yes","No")
A105: 46143 | B105: Salt Shark | C105: Freight DIFOT | E105: 0.95 | F105: 45 | G105: 49 | H105: =F158/G158 | I105: =IF(H158>=E158,"Yes","No") | J105: Below target - investigate root cause and add to next month's action plan
A106: 46143 | B106: Vixxen | C106: Freight DIFOT | E106: 0.95 | F106: 78 | G106: 82 | H106: =F159/G159 | I106: =IF(H159>=E159,"Yes","No")
...

Sheet Exceptions
A1: Exceptions
A3: Customer Cutoff Time Overrides
A4: Customer | B4: Cutoff Time (HH:MM, 24hr) | C4: Deadline Rule | D4: Effective From | E4: Effective To | F4: Reason | G4: After-cutoff extra business days | H4: Use packed timestamp (Y/N)
A5: Logwin - Sikla | B5: 12:00 | C5: Next business day (EOD) | D5: 46188 | F5: Customer-requested: orders received before 12pm NZ time may dispatch any time up to end of next business day | G5: 1 | H5: Y
A6: Coromandel Mountains Company Limited | B6: 14:00 | C6: Same day | D6: 46204 | F6: Invoice-ready-to-print workflow: dispatched timestamp is set on manual print run, not at actual dispatch. Use packed timestamp to reflect true fulfilment time. | G6: 0 | H6: Y
A7: Jock Freight - SECA | B7: 14:00 | C7: Same day | D7: 46204 | F7: Invoice-ready-to-print workflow: dispatched timestamp is set on manual print run, not at actual dispatch. Use packed timestamp to reflect true fulfilment time. | G7: 0 | H7: Y
A8: Simply Clean | B8: 00:00 | C8: Same day | D8: 46237 | E8: 46243 | F8: Customer-requested: extra 2 business days to process all orders received 3-9 Aug 2026 (operational delay this week). Cutoff time set to 00:00 so every order this week is treated as "after cutoff", giving the standard 1 business day plus 2 extra = 3 business days from creation to dispatch deadline, regardless of what time of day the order was created. | G8: 2
A9: Salt Shark | B9: 00:00 | C9: Same day | D9: 46262 | E9: 46264 | F9: Customer-requested: extra 1 business day to process orders received over the 28-30 Aug 2026 weekend (high order volume; majority of these orders being deleted, remaining ones need extra processing time). Cutoff time set to 00:00 so every order in this window is treated as "after cutoff", giving the standard 1 business day plus 1 extra = 2 business days from creation to dispatch deadline, regardless of what time of day the order was created. | G9: 1
A15: Deadline Rule must be either "Same day" or "Next business day (EOD)". Leave Effective To blank for an open-ended override. Overrides only make the deadline MORE lenient than the standard rule, never stricter.
A17: Order-Level Exceptions
A18: Date Logged | B18: Customer | C18: Order Reference | D18: Month (YYYY-MM) | E18: KPI | F18: Action | G18: Reason | H18: Date From | I18: Date To
A19: 46203 | B19: Cotton Soft - Christchurch | C19: 147 | D19: 2026-06 | E19: Dock to Stock | F19: Count as met | G19: Arrival and allocated dates manually corrected to 18-Jun in CartonCloud UI. API does not expose updated dates; counting as met per operations review.
A20: 46203 | B20: Cotton Soft - Christchurch | C20: 148 | D20: 2026-06 | E20: Dock to Stock | F20: Count as met | G20: Arrival and allocated dates manually corrected to 18-Jun in CartonCloud UI. API does not expose updated dates; counting as met per operations review.
A21: 46205 | B21: Salt Shark | C21: 1713 | D21: 2026-07 | E21: Order Cut Off | F21: Exclude from calculation | G21: Customer requested hold on orders 1-2 Jul 2026
A22: 46205 | B22: Salt Shark | C22: 1715 | D22: 2026-07 | E22: Order Cut Off | F22: Exclude from calculation | G22: Customer requested hold on orders 1-2 Jul 2026
A23: 46205 | B23: Salt Shark | C23: 1716 | D23: 2026-07 | E23: Order Cut Off | F23: Exclude from calculation | G23: Customer requested hold on orders 1-2 Jul 2026
A24: 46205 | B24: Salt Shark | C24: 1724 | D24: 2026-07 | E24: Order Cut Off | F24: Exclude from calculation | G24: Customer requested hold on orders 1-2 Jul 2026
A25: 46209 | B25: Made Group NZ | C25: 121 | D25: 2026-06 | E25: Dock to Stock | F25: Count as met | G25: Arrival dates corrected in CartonCloud UI — API does not reflect update. All POs confirmed as meeting 48hr target per operations review.
A26: 46209 | B26: Made Group NZ | C26: 122 | D26: 2026-06 | E26: Dock to Stock | F26: Count as met | G26: Arrival dates corrected in CartonCloud UI — API does not reflect update. All POs confirmed as meeting 48hr target per operations review.
A27: 46209 | B27: Made Group NZ | C27: 123 | D27: 2026-06 | E27: Dock to Stock | F27: Count as met | G27: Arrival dates corrected in CartonCloud UI — API does not reflect update. All POs confirmed as meeting 48hr target per operations review.
A28: 46209 | B28: Made Group NZ | C28: 124 | D28: 2026-06 | E28: Dock to Stock | F28: Count as met | G28: Arrival dates corrected in CartonCloud UI — API does not reflect update. All POs confirmed as meeting 48hr target per operations review.
A29: 46209 | B29: Made Group NZ | C29: 125 | D29: 2026-06 | E29: Dock to Stock | F29: Count as met | G29: Arrival dates corrected in CartonCloud UI — API does not reflect update. All POs confirmed as meeting 48hr target per operations review.
A30: 46209 | B30: Made Group NZ | C30: 126 | D30: 2026-06 | E30: Dock to Stock | F30: Count as met | G30: Arrival dates corrected in CartonCloud UI — API does not reflect update. All POs confirmed as meeting 48hr target per operations review.
... A35: 46209 | B35: Made Group NZ | C35: 131 | D35: 2026-06 | E35: Dock to Stock | F35: Count as met | G35: Arrival dates corrected in CartonCloud UI — API does not reflect update. All POs confirmed as meeting 48hr target per operations review.
A40: 46196
A41: 46196
A42: 46196
A43: 46196
A44: 46196
A45: 46196
A46: 46196
A47: 46196
A48: 46196
A49: 46196
A50: 46196
A51: 46196
... A60: 46196
A61: 46196 | F61: Count as met | G61: DC recipient exception - pre-arranged booking, excluded from avg delivery days
A62: 46196 | F62: Count as met | G62: DC recipient exception - pre-arranged booking, excluded from avg delivery days
A63: 46196
...

Sheet Issue Log
A1: Issue Log
A2: Feeds the Order Accuracy by Unit KPI. Log every fulfilment issue here as it's found - wrong item picked, wrong quantity, damaged on arrival, missing item, etc. Quantity Wrong is the number of UNITS affected by this specific issue (not the whole order's unit count unless the whole order was wrong). The month an issue counts against is taken from Date Logged, so log issues promptly, close to when the order shipped.
A4: Date Logged | B4: Customer | C4: Order Reference | D4: Quantity Wrong | E4: Issue Details
A5: 46245 | B5: Vixxen | C5: 3165 | D5: 1 | E5: Item 7006718003 Sculpt Bra - Size C ordered, Size B sent instead (wrong size picked)
A6: 46248 | B6: Simply Clean | C6: 11133 | D6: 1 | E6: Item 8289500070129 - ordered 1106073, incorrectly sent JD13 instead (inwards not done correctly)
A7: 46248 | B7: Vixxen | C7: INV-18027713 | D7: 8 | E7: Sent 2x silicone stick-on bras (D cup, additionals) instead of ordered D-cup wing stick-on bras; also sent 4x disposable nipple covers instead of ordered lacey heart nipple covers, missing 2x lacey heart ones. Total 8 units incorrect.
A8: 46248 | B8: Vixxen | C8: 3205 | D8: 1 | E8: Silicone stick-on bra - Size C ordered, Size D sent instead (wrong size picked)
A9: 46248 | B9: Vixxen | C9: 3206 | D9: 1 | E9: Silicone stick-on bra - Size A ordered, Size C sent instead (wrong size picked)

Sheet Dashboard_Calc
A1: Selected Customer | B1: =Dashboard!C4
A2: Latest Month | B2: =MAX(KPI_Data!A4:A295)
A4: Month | B4: Target | C4: Numerator | D4: Denominator | E4: Actual % | G4: Month | H4: Target | I4: Numerator | J4: Denominator | K4: Actual % | M4: Month | N4: Target | O4: Numerator | P4: Denominator | Q4: Actual % | S4: Month | T4: Target | U4: Numerator | V4: Denominator | W4: Actual % | Y4: Month | Z4: Target | AA4: Numerator | AB4: Denominator | AC4: Actual %
A5: =EDATE($B$2,-11) | B5: =INDEX('KPI Schedule'!$B$5:$B$10,MATCH("Dock to Stock",'KPI Schedule'!$A$5:$A$10,0)) | C5: =SUMIFS(KPI_Data!$F$4:$F$295,KPI_Data!$B$4:$B$295,$B$1,KPI_Data!$C$4:$C$295,"Dock to Stock",KPI_Data!$A$4:$A$295,A5) | D5: =SUMIFS(KPI_Data!$G$4:$G$295,KPI_Data!$B$4:$B$295,$B$1,KPI_Data!$C$4:$C$295,"Dock to Stock",KPI_Data!$A$4:$A$295,A5) | E5: =IFERROR(C5/D5,"") | G5: =EDATE($B$2,-11) | H5: =INDEX('KPI Schedule'!$B$5:$B$10,MATCH("Cycle Count",'KPI Schedule'!$A$5:$A$10,0)) | I5: =SUMIFS(KPI_Data!$F$4:$F$295,KPI_Data!$B$4:$B$295,$B$1,KPI_Data!$C$4:$C$295,"Cycle Count",KPI_Data!$A$4:$A$295,G5) | J5: =SUMIFS(KPI_Data!$G$4:$G$295,KPI_Data!$B$4:$B$295,$B$1,KPI_Data!$C$4:$C$295,"Cycle Count",KPI_Data!$A$4:$A$295,G5) | K5: =IFERROR(I5/J5,"") | M5: =EDATE($B$2,-11) | N5: =INDEX('KPI Schedule'!$B$5:$B$10,MATCH("Order Cut Off",'KPI Schedule'!$A$5:$A$10,0)) | O5: =SUMIFS(KPI_Data!$F$4:$F$295,KPI_Data!$B$4:$B$295,$B$1,KPI_Data!$C$4:$C$295,"Order Cut Off",KPI_Data!$A$4:$A$295,M5) | P5: =SUMIFS(KPI_Data!$G$4:$G$295,KPI_Data!$B$4:$B$295,$B$1,KPI_Data!$C$4:$C$295,"Order Cut Off",KPI_Data!$A$4:$A$295,M5) | Q5: =IFERROR(O5/P5,"") | S5: =EDATE($B$2,-11) | T5: =INDEX('KPI Schedule'!$B$5:$B$10,MATCH("Order Accuracy by Unit",'KPI Schedule'!$A$5:$A$10,0)) | U5: =SUMIFS(KPI_Data!$F$4:$F$295,KPI_Data!$B$4:$B$295,$B$1,KPI_Data!$C$4:$C$295,"Order Accuracy by Unit",KPI_Data!$A$4:$A$295,S5) | V5: =SUMIFS(KPI_Data!$G$4:$G$295,KPI_Data!$B$4:$B$295,$B$1,KPI_Data!$C$4:$C$295,"Order Accuracy by Unit",KPI_Data!$A$4:$A$295,S5) | W5: =IFERROR(U5/V5,"") | Y5: =EDATE($B$2,-11) | Z5: =INDEX('KPI Schedule'!$B$5:$B$10,MATCH("Freight DIFOT",'KPI Schedule'!$A$5:$A$10,0)) | AA5: =SUMIFS(KPI_Data!$F$4:$F$295,KPI_Data!$B$4:$B$295,$B$1,KPI_Data!$C$4:$C$295,"Freight DIFOT",KPI_Data!$A$4:$A$295,Y5) | AB5: =SUMIFS(KPI_Data!$G$4:$G$295,KPI_Data!$B$4:$B$295,$B$1,KPI_Data!$C$4:$C$295,"Freight DIFOT",KPI_Data!$A$4:$A$295,Y5) | AC5: =IFERROR(AA5/AB5,"")
A6: =EDATE(A5,1) | B6: =INDEX('KPI Schedule'!$B$5:$B$10,MATCH("Dock to Stock",'KPI Schedule'!$A$5:$A$10,0)) | C6: =SUMIFS(KPI_Data!$F$4:$F$295,KPI_Data!$B$4:$B$295,$B$1,KPI_Data!$C$4:$C$295,"Dock to Stock",KPI_Data!$A$4:$A$295,A6) | D6: =SUMIFS(KPI_Data!$G$4:$G$295,KPI_Data!$B$4:$B$295,$B$1,KPI_Data!$C$4:$C$295,"Dock to Stock",KPI_Data!$A$4:$A$295,A6) | E6: =IFERROR(C6/D6,"") | G6: =EDATE(G5,1) | H6: =INDEX('KPI Schedule'!$B$5:$B$10,MATCH("Cycle Count",'KPI Schedule'!$A$5:$A$10,0)) | I6: =SUMIFS(KPI_Data!$F$4:$F$295,KPI_Data!$B$4:$B$295,$B$1,KPI_Data!$C$4:$C$295,"Cycle Count",KPI_Data!$A$4:$A$295,G6) | J6: =SUMIFS(KPI_Data!$G$4:$G$295,KPI_Data!$B$4:$B$295,$B$1,KPI_Data!$C$4:$C$295,"Cycle Count",KPI_Data!$A$4:$A$295,G6) | K6: =IFERROR(I6/J6,"") | M6: =EDATE(M5,1) | N6: =INDEX('KPI Schedule'!$B$5:$B$10,MATCH("Order Cut Off",'KPI Schedule'!$A$5:$A$10,0)) | O6: =SUMIFS(KPI_Data!$F$4:$F$295,KPI_Data!$B$4:$B$295,$B$1,KPI_Data!$C$4:$C$295,"Order Cut Off",KPI_Data!$A$4:$A$295,M6) | P6: =SUMIFS(KPI_Data!$G$4:$G$295,KPI_Data!$B$4:$B$295,$B$1,KPI_Data!$C$4:$C$295,"Order Cut Off",KPI_Data!$A$4:$A$295,M6) | Q6: =IFERROR(O6/P6,"") | S6: =EDATE(S5,1) | T6: =INDEX('KPI Schedule'!$B$5:$B$10,MATCH("Order Accuracy by Unit",'KPI Schedule'!$A$5:$A$10,0)) | U6: =SUMIFS(KPI_Data!$F$4:$F$295,KPI_Data!$B$4:$B$295,$B$1,KPI_Data!$C$4:$C$295,"Order Accuracy by Unit",KPI_Data!$A$4:$A$295,S6) | V6: =SUMIFS(KPI_Data!$G$4:$G$295,KPI_Data!$B$4:$B$295,$B$1,KPI_Data!$C$4:$C$295,"Order Accuracy by Unit",KPI_Data!$A$4:$A$295,S6) | W6: =IFERROR(U6/V6,"") | Y6: =EDATE(Y5,1) | Z6: =INDEX('KPI Schedule'!$B$5:$B$10,MATCH("Freight DIFOT",'KPI Schedule'!$A$5:$A$10,0)) | AA6: =SUMIFS(KPI_Data!$F$4:$F$295,KPI_Data!$B$4:$B$295,$B$1,KPI_Data!$C$4:$C$295,"Freight DIFOT",KPI_Data!$A$4:$A$295,Y6) | AB6: =SUMIFS(KPI_Data!$G$4:$G$295,KPI_Data!$B$4:$B$295,$B$1,KPI_Data!$C$4:$C$295,"Freight DIFOT",KPI_Data!$A$4:$A$295,Y6) | AC6: =IFERROR(AA6/AB6,"")
A7: =EDATE(A6,1) | B7: =INDEX('KPI Schedule'!$B$5:$B$10,MATCH("Dock to Stock",'KPI Schedule'!$A$5:$A$10,0)) | C7: =SUMIFS(KPI_Data!$F$4:$F$295,KPI_Data!$B$4:$B$295,$B$1,KPI_Data!$C$4:$C$295,"Dock to Stock",KPI_Data!$A$4:$A$295,A7) | D7: =SUMIFS(KPI_Data!$G$4:$G$295,KPI_Data!$B$4:$B$295,$B$1,KPI_Data!$C$4:$C$295,"Dock to Stock",KPI_Data!$A$4:$A$295,A7) | E7: =IFERROR(C7/D7,"") | G7: =EDATE(G6,1) | H7: =INDEX('KPI Schedule'!$B$5:$B$10,MATCH("Cycle Count",'KPI Schedule'!$A$5:$A$10,0)) | I7: =SUMIFS(KPI_Data!$F$4:$F$295,KPI_Data!$B$4:$B$295,$B$1,KPI_Data!$C$4:$C$295,"Cycle Count",KPI_Data!$A$4:$A$295,G7) | J7: =SUMIFS(KPI_Data!$G$4:$G$295,KPI_Data!$B$4:$B$295,$B$1,KPI_Data!$C$4:$C$295,"Cycle Count",KPI_Data!$A$4:$A$295,G7) | K7: =IFERROR(I7/J7,"") | M7: =EDATE(M6,1) | N7: =INDEX('KPI Schedule'!$B$5:$B$10,MATCH("Order Cut Off",'KPI Schedule'!$A$5:$A$10,0)) | O7: =SUMIFS(KPI_Data!$F$4:$F$295,KPI_Data!$B$4:$B$295,$B$1,KPI_Data!$C$4:$C$295,"Order Cut Off",KPI_Data!$A$4:$A$295,M7) | P7: =SUMIFS(KPI_Data!$G$4:$G$295,KPI_Data!$B$4:$B$295,$B$1,KPI_Data!$C$4:$C$295,"Order Cut Off",KPI_Data!$A$4:$A$295,M7) | Q7: =IFERROR(O7/P7,"") | S7: =EDATE(S6,1) | T7: =INDEX('KPI Schedule'!$B$5:$B$10,MATCH("Order Accuracy by Unit",'KPI Schedule'!$A$5:$A$10,0)) | U7: =SUMIFS(KPI_Data!$F$4:$F$295,KPI_Data!$B$4:$B$295,$B$1,KPI_Data!$C$4:$C$295,"Order Accuracy by Unit",KPI_Data!$A$4:$A$295,S7) | V7: =SUMIFS(KPI_Data!$G$4:$G$295,KPI_Data!$B$4:$B$295,$B$1,KPI_Data!$C$4:$C$295,"Order Accuracy by Unit",KPI_Data!$A$4:$A$295,S7) | W7: =IFERROR(U7/V7,"") | Y7: =EDATE(Y6,1) | Z7: =INDEX('KPI Schedule'!$B$5:$B$10,MATCH("Freight DIFOT",'KPI Schedule'!$A$5:$A$10,0)) | AA7: =SUMIFS(KPI_Data!$F$4:$F$295,KPI_Data!$B$4:$B$295,$B$1,KPI_Data!$C$4:$C$295,"Freight DIFOT",KPI_Data!$A$4:$A$295,Y7) | AB7: =SUMIFS(KPI_Data!$G$4:$G$295,KPI_Data!$B$4:$B$295,$B$1,KPI_Data!$C$4:$C$295,"Freight DIFOT",KPI_Data!$A$4:$A$295,Y7) | AC7: =IFERROR(AA7/AB7,"")
A8: =EDATE(A7,1) | B8: =INDEX('KPI Schedule'!$B$5:$B$10,MATCH("Dock to Stock",'KPI Schedule'!$A$5:$A$10,0)) | C8: =SUMIFS(KPI_Data!$F$4:$F$295,KPI_Data!$B$4:$B$295,$B$1,KPI_Data!$C$4:$C$295,"Dock to Stock",KPI_Data!$A$4:$A$295,A8) | D8: =SUMIFS(KPI_Data!$G$4:$G$295,KPI_Data!$B$4:$B$295,$B$1,KPI_Data!$C$4:$C$295,"Dock to Stock",KPI_Data!$A$4:$A$295,A8) | E8: =IFERROR(C8/D8,"") | G8: =EDATE(G7,1) | H8: =INDEX('KPI Schedule'!$B$5:$B$10,MATCH("Cycle Count",'KPI Schedule'!$A$5:$A$10,0)) | I8: =SUMIFS(KPI_Data!$F$4:$F$295,KPI_Data!$B$4:$B$295,$B$1,KPI_Data!$C$4:$C$295,"Cycle Count",KPI_Data!$A$4:$A$295,G8) | J8: =SUMIFS(KPI_Data!$G$4:$G$295,KPI_Data!$B$4:$B$295,$B$1,KPI_Data!$C$4:$C$295,"Cycle Count",KPI_Data!$A$4:$A$295,G8) | K8: =IFERROR(I8/J8,"") | M8: =EDATE(M7,1) | N8: =INDEX('KPI Schedule'!$B$5:$B$10,MATCH("Order Cut Off",'KPI Schedule'!$A$5:$A$10,0)) | O8: =SUMIFS(KPI_Data!$F$4:$F$295,KPI_Data!$B$4:$B$295,$B$1,KPI_Data!$C$4:$C$295,"Order Cut Off",KPI_Data!$A$4:$A$295,M8) | P8: =SUMIFS(KPI_Data!$G$4:$G$295,KPI_Data!$B$4:$B$295,$B$1,KPI_Data!$C$4:$C$295,"Order Cut Off",KPI_Data!$A$4:$A$295,M8) | Q8: =IFERROR(O8/P8,"") | S8: =EDATE(S7,1) | T8: =INDEX('KPI Schedule'!$B$5:$B$10,MATCH("Order Accuracy by Unit",'KPI Schedule'!$A$5:$A$10,0)) | U8: =SUMIFS(KPI_Data!$F$4:$F$295,KPI_Data!$B$4:$B$295,$B$1,KPI_Data!$C$4:$C$295,"Order Accuracy by Unit",KPI_Data!$A$4:$A$295,S8) | V8: =SUMIFS(KPI_Data!$G$4:$G$295,KPI_Data!$B$4:$B$295,$B$1,KPI_Data!$C$4:$C$295,"Order Accuracy by Unit",KPI_Data!$A$4:$A$295,S8) | W8: =IFERROR(U8/V8,"") | Y8: =EDATE(Y7,1) | Z8: =INDEX('KPI Schedule'!$B$5:$B$10,MATCH("Freight DIFOT",'KPI Schedule'!$A$5:$A$10,0)) | AA8: =SUMIFS(KPI_Data!$F$4:$F$295,KPI_Data!$B$4:$B$295,$B$1,KPI_Data!$C$4:$C$295,"Freight DIFOT",KPI_Data!$A$4:$A$295,Y8) | AB8: =SUMIFS(KPI_Data!$G$4:$G$295,KPI_Data!$B$4:$B$295,$B$1,KPI_Data!$C$4:$C$295,"Freight DIFOT",KPI_Data!$A$4:$A$295,Y8) | AC8: =IFERROR(AA8/AB8,"")
A9: =EDATE(A8,1) | B9: =INDEX('KPI Schedule'!$B$5:$B$10,MATCH("Dock to Stock",'KPI Schedule'!$A$5:$A$10,0)) | C9: =SUMIFS(KPI_Data!$F$4:$F$295,KPI_Data!$B$4:$B$295,$B$1,KPI_Data!$C$4:$C$295,"Dock to Stock",KPI_Data!$A$4:$A$295,A9) | D9: =SUMIFS(KPI_Data!$G$4:$G$295,KPI_Data!$B$4:$B$295,$B$1,KPI_Data!$C$4:$C$295,"Dock to Stock",KPI_Data!$A$4:$A$295,A9) | E9: =IFERROR(C9/D9,"") | G9: =EDATE(G8,1) | H9: =INDEX('KPI Schedule'!$B$5:$B$10,MATCH("Cycle Count",'KPI Schedule'!$A$5:$A$10,0)) | I9: =SUMIFS(KPI_Data!$F$4:$F$295,KPI_Data!$B$4:$B$295,$B$1,KPI_Data!$C$4:$C$295,"Cycle Count",KPI_Data!$A$4:$A$295,G9) | J9: =SUMIFS(KPI_Data!$G$4:$G$295,KPI_Data!$B$4:$B$295,$B$1,KPI_Data!$C$4:$C$295,"Cycle Count",KPI_Data!$A$4:$A$295,G9) | K9: =IFERROR(I9/J9,"") | M9: =EDATE(M8,1) | N9: =INDEX('KPI Schedule'!$B$5:$B$10,MATCH("Order Cut Off",'KPI Schedule'!$A$5:$A$10,0)) | O9: =SUMIFS(KPI_Data!$F$4:$F$295,KPI_Data!$B$4:$B$295,$B$1,KPI_Data!$C$4:$C$295,"Order Cut Off",KPI_Data!$A$4:$A$295,M9) | P9: =SUMIFS(KPI_Data!$G$4:$G$295,KPI_Data!$B$4:$B$295,$B$1,KPI_Data!$C$4:$C$295,"Order Cut Off",KPI_Data!$A$4:$A$295,M9) | Q9: =IFERROR(O9/P9,"") | S9: =EDATE(S8,1) | T9: =INDEX('KPI Schedule'!$B$5:$B$10,MATCH("Order Accuracy by Unit",'KPI Schedule'!$A$5:$A$10,0)) | U9: =SUMIFS(KPI_Data!$F$4:$F$295,KPI_Data!$B$4:$B$295,$B$1,KPI_Data!$C$4:$C$295,"Order Accuracy by Unit",KPI_Data!$A$4:$A$295,S9) | V9: =SUMIFS(KPI_Data!$G$4:$G$295,KPI_Data!$B$4:$B$295,$B$1,KPI_Data!$C$4:$C$295,"Order Accuracy by Unit",KPI_Data!$A$4:$A$295,S9) | W9: =IFERROR(U9/V9,"") | Y9: =EDATE(Y8,1) | Z9: =INDEX('KPI Schedule'!$B$5:$B$10,MATCH("Freight DIFOT",'KPI Schedule'!$A$5:$A$10,0)) | AA9: =SUMIFS(KPI_Data!$F$4:$F$295,KPI_Data!$B$4:$B$295,$B$1,KPI_Data!$C$4:$C$295,"Freight DIFOT",KPI_Data!$A$4:$A$295,Y9) | AB9: =SUMIFS(KPI_Data!$G$4:$G$295,KPI_Data!$B$4:$B$295,$B$1,KPI_Data!$C$4:$C$295,"Freight DIFOT",KPI_Data!$A$4:$A$295,Y9) | AC9: =IFERROR(AA9/AB9,"")
A10: =EDATE(A9,1) | B10: =INDEX('KPI Schedule'!$B$5:$B$10,MATCH("Dock to Stock",'KPI Schedule'!$A$5:$A$10,0)) | C10: =SUMIFS(KPI_Data!$F$4:$F$295,KPI_Data!$B$4:$B$295,$B$1,KPI_Data!$C$4:$C$295,"Dock to Stock",KPI_Data!$A$4:$A$295,A10) | D10: =SUMIFS(KPI_Data!$G$4:$G$295,KPI_Data!$B$4:$B$295,$B$1,KPI_Data!$C$4:$C$295,"Dock to Stock",KPI_Data!$A$4:$A$295,A10) | E10: =IFERROR(C10/D10,"") | G10: =EDATE(G9,1) | H10: =INDEX('KPI Schedule'!$B$5:$B$10,MATCH("Cycle Count",'KPI Schedule'!$A$5:$A$10,0)) | I10: =SUMIFS(KPI_Data!$F$4:$F$295,KPI_Data!$B$4:$B$295,$B$1,KPI_Data!$C$4:$C$295,"Cycle Count",KPI_Data!$A$4:$A$295,G10) | J10: =SUMIFS(KPI_Data!$G$4:$G$295,KPI_Data!$B$4:$B$295,$B$1,KPI_Data!$C$4:$C$295,"Cycle Count",KPI_Data!$A$4:$A$295,G10) | K10: =IFERROR(I10/J10,"") | M10: =EDATE(M9,1) | N10: =INDEX('KPI Schedule'!$B$5:$B$10,MATCH("Order Cut Off",'KPI Schedule'!$A$5:$A$10,0)) | O10: =SUMIFS(KPI_Data!$F$4:$F$295,KPI_Data!$B$4:$B$295,$B$1,KPI_Data!$C$4:$C$295,"Order Cut Off",KPI_Data!$A$4:$A$295,M10) | P10: =SUMIFS(KPI_Data!$G$4:$G$295,KPI_Data!$B$4:$B$295,$B$1,KPI_Data!$C$4:$C$295,"Order Cut Off",KPI_Data!$A$4:$A$295,M10) | Q10: =IFERROR(O10/P10,"") | S10: =EDATE(S9,1) | T10: =INDEX('KPI Schedule'!$B$5:$B$10,MATCH("Order Accuracy by Unit",'KPI Schedule'!$A$5:$A$10,0)) | U10: =SUMIFS(KPI_Data!$F$4:$F$295,KPI_Data!$B$4:$B$295,$B$1,KPI_Data!$C$4:$C$295,"Order Accuracy by Unit",KPI_Data!$A$4:$A$295,S10) | V10: =SUMIFS(KPI_Data!$G$4:$G$295,KPI_Data!$B$4:$B$295,$B$1,KPI_Data!$C$4:$C$295,"Order Accuracy by Unit",KPI_Data!$A$4:$A$295,S10) | W10: =IFERROR(U10/V10,"") | Y10: =EDATE(Y9,1) | Z10: =INDEX('KPI Schedule'!$B$5:$B$10,MATCH("Freight DIFOT",'KPI Schedule'!$A$5:$A$10,0)) | AA10: =SUMIFS(KPI_Data!$F$4:$F$295,KPI_Data!$B$4:$B$295,$B$1,KPI_Data!$C$4:$C$295,"Freight DIFOT",KPI_Data!$A$4:$A$295,Y10) | AB10: =SUMIFS(KPI_Data!$G$4:$G$295,KPI_Data!$B$4:$B$295,$B$1,KPI_Data!$C$4:$C$295,"Freight DIFOT",KPI_Data!$A$4:$A$295,Y10) | AC10: =IFERROR(AA10/AB10,"")
A11: =EDATE(A10,1) | B11: =INDEX('KPI Schedule'!$B$5:$B$10,MATCH("Dock to Stock",'KPI Schedule'!$A$5:$A$10,0)) | C11: =SUMIFS(KPI_Data!$F$4:$F$295,KPI_Data!$B$4:$B$295,$B$1,KPI_Data!$C$4:$C$295,"Dock to Stock",KPI_Data!$A$4:$A$295,A11) | D11: =SUMIFS(KPI_Data!$G$4:$G$295,KPI_Data!$B$4:$B$295,$B$1,KPI_Data!$C$4:$C$295,"Dock to Stock",KPI_Data!$A$4:$A$295,A11) | E11: =IFERROR(C11/D11,"") | G11: =EDATE(G10,1) | H11: =INDEX('KPI Schedule'!$B$5:$B$10,MATCH("Cycle Count",'KPI Schedule'!$A$5:$A$10,0)) | I11: =SUMIFS(KPI_Data!$F$4:$F$295,KPI_Data!$B$4:$B$295,$B$1,KPI_Data!$C$4:$C$295,"Cycle Count",KPI_Data!$A$4:$A$295,G11) | J11: =SUMIFS(KPI_Data!$G$4:$G$295,KPI_Data!$B$4:$B$295,$B$1,KPI_Data!$C$4:$C$295,"Cycle Count",KPI_Data!$A$4:$A$295,G11) | K11: =IFERROR(I11/J11,"") | M11: =EDATE(M10,1) | N11: =INDEX('KPI Schedule'!$B$5:$B$10,MATCH("Order Cut Off",'KPI Schedule'!$A$5:$A$10,0)) | O11: =SUMIFS(KPI_Data!$F$4:$F$295,KPI_Data!$B$4:$B$295,$B$1,KPI_Data!$C$4:$C$295,"Order Cut Off",KPI_Data!$A$4:$A$295,M11) | P11: =SUMIFS(KPI_Data!$G$4:$G$295,KPI_Data!$B$4:$B$295,$B$1,KPI_Data!$C$4:$C$295,"Order Cut Off",KPI_Data!$A$4:$A$295,M11) | Q11: =IFERROR(O11/P11,"") | S11: =EDATE(S10,1) | T11: =INDEX('KPI Schedule'!$B$5:$B$10,MATCH("Order Accuracy by Unit",'KPI Schedule'!$A$5:$A$10,0)) | U11: =SUMIFS(KPI_Data!$F$4:$F$295,KPI_Data!$B$4:$B$295,$B$1,KPI_Data!$C$4:$C$295,"Order Accuracy by Unit",KPI_Data!$A$4:$A$295,S11) | V11: =SUMIFS(KPI_Data!$G$4:$G$295,KPI_Data!$B$4:$B$295,$B$1,KPI_Data!$C$4:$C$295,"Order Accuracy by Unit",KPI_Data!$A$4:$A$295,S11) | W11: =IFERROR(U11/V11,"") | Y11: =EDATE(Y10,1) | Z11: =INDEX('KPI Schedule'!$B$5:$B$10,MATCH("Freight DIFOT",'KPI Schedule'!$A$5:$A$10,0)) | AA11: =SUMIFS(KPI_Data!$F$4:$F$295,KPI_Data!$B$4:$B$295,$B$1,KPI_Data!$C$4:$C$295,"Freight DIFOT",KPI_Data!$A$4:$A$295,Y11) | AB11: =SUMIFS(KPI_Data!$G$4:$G$295,KPI_Data!$B$4:$B$295,$B$1,KPI_Data!$C$4:$C$295,"Freight DIFOT",KPI_Data!$A$4:$A$295,Y11) | AC11: =IFERROR(AA11/AB11,"")
A12: =EDATE(A11,1) | B12: =INDEX('KPI Schedule'!$B$5:$B$10,MATCH("Dock to Stock",'KPI Schedule'!$A$5:$A$10,0)) | C12: =SUMIFS(KPI_Data!$F$4:$F$295,KPI_Data!$B$4:$B$295,$B$1,KPI_Data!$C$4:$C$295,"Dock to Stock",KPI_Data!$A$4:$A$295,A12) | D12: =SUMIFS(KPI_Data!$G$4:$G$295,KPI_Data!$B$4:$B$295,$B$1,KPI_Data!$C$4:$C$295,"Dock to Stock",KPI_Data!$A$4:$A$295,A12) | E12: =IFERROR(C12/D12,"") | G12: =EDATE(G11,1) | H12: =INDEX('KPI Schedule'!$B$5:$B$10,MATCH("Cycle Count",'KPI Schedule'!$A$5:$A$10,0)) | I12: =SUMIFS(KPI_Data!$F$4:$F$295,KPI_Data!$B$4:$B$295,$B$1,KPI_Data!$C$4:$C$295,"Cycle Count",KPI_Data!$A$4:$A$295,G12) | J12: =SUMIFS(KPI_Data!$G$4:$G$295,KPI_Data!$B$4:$B$295,$B$1,KPI_Data!$C$4:$C$295,"Cycle Count",KPI_Data!$A$4:$A$295,G12) | K12: =IFERROR(I12/J12,"") | M12: =EDATE(M11,1) | N12: =INDEX('KPI Schedule'!$B$5:$B$10,MATCH("Order Cut Off",'KPI Schedule'!$A$5:$A$10,0)) | O12: =SUMIFS(KPI_Data!$F$4:$F$295,KPI_Data!$B$4:$B$295,$B$1,KPI_Data!$C$4:$C$295,"Order Cut Off",KPI_Data!$A$4:$A$295,M12) | P12: =SUMIFS(KPI_Data!$G$4:$G$295,KPI_Data!$B$4:$B$295,$B$1,KPI_Data!$C$4:$C$295,"Order Cut Off",KPI_Data!$A$4:$A$295,M12) | Q12: =IFERROR(O12/P12,"") | S12: =EDATE(S11,1) | T12: =INDEX('KPI Schedule'!$B$5:$B$10,MATCH("Order Accuracy by Unit",'KPI Schedule'!$A$5:$A$10,0)) | U12: =SUMIFS(KPI_Data!$F$4:$F$295,KPI_Data!$B$4:$B$295,$B$1,KPI_Data!$C$4:$C$295,"Order Accuracy by Unit",KPI_Data!$A$4:$A$295,S12) | V12: =SUMIFS(KPI_Data!$G$4:$G$295,KPI_Data!$B$4:$B$295,$B$1,KPI_Data!$C$4:$C$295,"Order Accuracy by Unit",KPI_Data!$A$4:$A$295,S12) | W12: =IFERROR(U12/V12,"") | Y12: =EDATE(Y11,1) | Z12: =INDEX('KPI Schedule'!$B$5:$B$10,MATCH("Freight DIFOT",'KPI Schedule'!$A$5:$A$10,0)) | AA12: =SUMIFS(KPI_Data!$F$4:$F$295,KPI_Data!$B$4:$B$295,$B$1,KPI_Data!$C$4:$C$295,"Freight DIFOT",KPI_Data!$A$4:$A$295,Y12) | AB12: =SUMIFS(KPI_Data!$G$4:$G$295,KPI_Data!$B$4:$B$295,$B$1,KPI_Data!$C$4:$C$295,"Freight DIFOT",KPI_Data!$A$4:$A$295,Y12) | AC12: =IFERROR(AA12/AB12,"")
A13: =EDATE(A12,1) | B13: =INDEX('KPI Schedule'!$B$5:$B$10,MATCH("Dock to Stock",'KPI Schedule'!$A$5:$A$10,0)) | C13: =SUMIFS(KPI_Data!$F$4:$F$295,KPI_Data!$B$4:$B$295,$B$1,KPI_Data!$C$4:$C$295,"Dock to Stock",KPI_Data!$A$4:$A$295,A13) | D13: =SUMIFS(KPI_Data!$G$4:$G$295,KPI_Data!$B$4:$B$295,$B$1,KPI_Data!$C$4:$C$295,"Dock to Stock",KPI_Data!$A$4:$A$295,A13) | E13: =IFERROR(C13/D13,"") | G13: =EDATE(G12,1) | H13: =INDEX('KPI Schedule'!$B$5:$B$10,MATCH("Cycle Count",'KPI Schedule'!$A$5:$A$10,0)) | I13: =SUMIFS(KPI_Data!$F$4:$F$295,KPI_Data!$B$4:$B$295,$B$1,KPI_Data!$C$4:$C$295,"Cycle Count",KPI_Data!$A$4:$A$295,G13) | J13: =SUMIFS(KPI_Data!$G$4:$G$295,KPI_Data!$B$4:$B$295,$B$1,KPI_Data!$C$4:$C$295,"Cycle Count",KPI_Data!$A$4:$A$295,G13) | K13: =IFERROR(I13/J13,"") | M13: =EDATE(M12,1) | N13: =INDEX('KPI Schedule'!$B$5:$B$10,MATCH("Order Cut Off",'KPI Schedule'!$A$5:$A$10,0)) | O13: =SUMIFS(KPI_Data!$F$4:$F$295,KPI_Data!$B$4:$B$295,$B$1,KPI_Data!$C$4:$C$295,"Order Cut Off",KPI_Data!$A$4:$A$295,M13) | P13: =SUMIFS(KPI_Data!$G$4:$G$295,KPI_Data!$B$4:$B$295,$B$1,KPI_Data!$C$4:$C$295,"Order Cut Off",KPI_Data!$A$4:$A$295,M13) | Q13: =IFERROR(O13/P13,"") | S13: =EDATE(S12,1) | T13: =INDEX('KPI Schedule'!$B$5:$B$10,MATCH("Order Accuracy by Unit",'KPI Schedule'!$A$5:$A$10,0)) | U13: =SUMIFS(KPI_Data!$F$4:$F$295,KPI_Data!$B$4:$B$295,$B$1,KPI_Data!$C$4:$C$295,"Order Accuracy by Unit",KPI_Data!$A$4:$A$295,S13) | V13: =SUMIFS(KPI_Data!$G$4:$G$295,KPI_Data!$B$4:$B$295,$B$1,KPI_Data!$C$4:$C$295,"Order Accuracy by Unit",KPI_Data!$A$4:$A$295,S13) | W13: =IFERROR(U13/V13,"") | Y13: =EDATE(Y12,1) | Z13: =INDEX('KPI Schedule'!$B$5:$B$10,MATCH("Freight DIFOT",'KPI Schedule'!$A$5:$A$10,0)) | AA13: =SUMIFS(KPI_Data!$F$4:$F$295,KPI_Data!$B$4:$B$295,$B$1,KPI_Data!$C$4:$C$295,"Freight DIFOT",KPI_Data!$A$4:$A$295,Y13) | AB13: =SUMIFS(KPI_Data!$G$4:$G$295,KPI_Data!$B$4:$B$295,$B$1,KPI_Data!$C$4:$C$295,"Freight DIFOT",KPI_Data!$A$4:$A$295,Y13) | AC13: =IFERROR(AA13/AB13,"")
A14: =EDATE(A13,1) | B14: =INDEX('KPI Schedule'!$B$5:$B$10,MATCH("Dock to Stock",'KPI Schedule'!$A$5:$A$10,0)) | C14: =SUMIFS(KPI_Data!$F$4:$F$295,KPI_Data!$B$4:$B$295,$B$1,KPI_Data!$C$4:$C$295,"Dock to Stock",KPI_Data!$A$4:$A$295,A14) | D14: =SUMIFS(KPI_Data!$G$4:$G$295,KPI_Data!$B$4:$B$295,$B$1,KPI_Data!$C$4:$C$295,"Dock to Stock",KPI_Data!$A$4:$A$295,A14) | E14: =IFERROR(C14/D14,"") | G14: =EDATE(G13,1) | H14: =INDEX('KPI Schedule'!$B$5:$B$10,MATCH("Cycle Count",'KPI Schedule'!$A$5:$A$10,0)) | I14: =SUMIFS(KPI_Data!$F$4:$F$295,KPI_Data!$B$4:$B$295,$B$1,KPI_Data!$C$4:$C$295,"Cycle Count",KPI_Data!$A$4:$A$295,G14) | J14: =SUMIFS(KPI_Data!$G$4:$G$295,KPI_Data!$B$4:$B$295,$B$1,KPI_Data!$C$4:$C$295,"Cycle Count",KPI_Data!$A$4:$A$295,G14) | K14: =IFERROR(I14/J14,"") | M14: =EDATE(M13,1) | N14: =INDEX('KPI Schedule'!$B$5:$B$10,MATCH("Order Cut Off",'KPI Schedule'!$A$5:$A$10,0)) | O14: =SUMIFS(KPI_Data!$F$4:$F$295,KPI_Data!$B$4:$B$295,$B$1,KPI_Data!$C$4:$C$295,"Order Cut Off",KPI_Data!$A$4:$A$295,M14) | P14: =SUMIFS(KPI_Data!$G$4:$G$295,KPI_Data!$B$4:$B$295,$B$1,KPI_Data!$C$4:$C$295,"Order Cut Off",KPI_Data!$A$4:$A$295,M14) | Q14: =IFERROR(O14/P14,"") | S14: =EDATE(S13,1) | T14: =INDEX('KPI Schedule'!$B$5:$B$10,MATCH("Order Accuracy by Unit",'KPI Schedule'!$A$5:$A$10,0)) | U14: =SUMIFS(KPI_Data!$F$4:$F$295,KPI_Data!$B$4:$B$295,$B$1,KPI_Data!$C$4:$C$295,"Order Accuracy by Unit",KPI_Data!$A$4:$A$295,S14) | V14: =SUMIFS(KPI_Data!$G$4:$G$295,KPI_Data!$B$4:$B$295,$B$1,KPI_Data!$C$4:$C$295,"Order Accuracy by Unit",KPI_Data!$A$4:$A$295,S14) | W14: =IFERROR(U14/V14,"") | Y14: =EDATE(Y13,1) | Z14: =INDEX('KPI Schedule'!$B$5:$B$10,MATCH("Freight DIFOT",'KPI Schedule'!$A$5:$A$10,0)) | AA14: =SUMIFS(KPI_Data!$F$4:$F$295,KPI_Data!$B$4:$B$295,$B$1,KPI_Data!$C$4:$C$295,"Freight DIFOT",KPI_Data!$A$4:$A$295,Y14) | AB14: =SUMIFS(KPI_Data!$G$4:$G$295,KPI_Data!$B$4:$B$295,$B$1,KPI_Data!$C$4:$C$295,"Freight DIFOT",KPI_Data!$A$4:$A$295,Y14) | AC14: =IFERROR(AA14/AB14,"")
A15: =EDATE(A14,1) | B15: =INDEX('KPI Schedule'!$B$5:$B$10,MATCH("Dock to Stock",'KPI Schedule'!$A$5:$A$10,0)) | C15: =SUMIFS(KPI_Data!$F$4:$F$295,KPI_Data!$B$4:$B$295,$B$1,KPI_Data!$C$4:$C$295,"Dock to Stock",KPI_Data!$A$4:$A$295,A15) | D15: =SUMIFS(KPI_Data!$G$4:$G$295,KPI_Data!$B$4:$B$295,$B$1,KPI_Data!$C$4:$C$295,"Dock to Stock",KPI_Data!$A$4:$A$295,A15) | E15: =IFERROR(C15/D15,"") | G15: =EDATE(G14,1) | H15: =INDEX('KPI Schedule'!$B$5:$B$10,MATCH("Cycle Count",'KPI Schedule'!$A$5:$A$10,0)) | I15: =SUMIFS(KPI_Data!$F$4:$F$295,KPI_Data!$B$4:$B$295,$B$1,KPI_Data!$C$4:$C$295,"Cycle Count",KPI_Data!$A$4:$A$295,G15) | J15: =SUMIFS(KPI_Data!$G$4:$G$295,KPI_Data!$B$4:$B$295,$B$1,KPI_Data!$C$4:$C$295,"Cycle Count",KPI_Data!$A$4:$A$295,G15) | K15: =IFERROR(I15/J15,"") | M15: =EDATE(M14,1) | N15: =INDEX('KPI Schedule'!$B$5:$B$10,MATCH("Order Cut Off",'KPI Schedule'!$A$5:$A$10,0)) | O15: =SUMIFS(KPI_Data!$F$4:$F$295,KPI_Data!$B$4:$B$295,$B$1,KPI_Data!$C$4:$C$295,"Order Cut Off",KPI_Data!$A$4:$A$295,M15) | P15: =SUMIFS(KPI_Data!$G$4:$G$295,KPI_Data!$B$4:$B$295,$B$1,KPI_Data!$C$4:$C$295,"Order Cut Off",KPI_Data!$A$4:$A$295,M15) | Q15: =IFERROR(O15/P15,"") | S15: =EDATE(S14,1) | T15: =INDEX('KPI Schedule'!$B$5:$B$10,MATCH("Order Accuracy by Unit",'KPI Schedule'!$A$5:$A$10,0)) | U15: =SUMIFS(KPI_Data!$F$4:$F$295,KPI_Data!$B$4:$B$295,$B$1,KPI_Data!$C$4:$C$295,"Order Accuracy by Unit",KPI_Data!$A$4:$A$295,S15) | V15: =SUMIFS(KPI_Data!$G$4:$G$295,KPI_Data!$B$4:$B$295,$B$1,KPI_Data!$C$4:$C$295,"Order Accuracy by Unit",KPI_Data!$A$4:$A$295,S15) | W15: =IFERROR(U15/V15,"") | Y15: =EDATE(Y14,1) | Z15: =INDEX('KPI Schedule'!$B$5:$B$10,MATCH("Freight DIFOT",'KPI Schedule'!$A$5:$A$10,0)) | AA15: =SUMIFS(KPI_Data!$F$4:$F$295,KPI_Data!$B$4:$B$295,$B$1,KPI_Data!$C$4:$C$295,"Freight DIFOT",KPI_Data!$A$4:$A$295,Y15) | AB15: =SUMIFS(KPI_Data!$G$4:$G$295,KPI_Data!$B$4:$B$295,$B$1,KPI_Data!$C$4:$C$295,"Freight DIFOT",KPI_Data!$A$4:$A$295,Y15) | AC15: =IFERROR(AA15/AB15,"")
A16: =EDATE(A15,1) | B16: =INDEX('KPI Schedule'!$B$5:$B$10,MATCH("Dock to Stock",'KPI Schedule'!$A$5:$A$10,0)) | C16: =SUMIFS(KPI_Data!$F$4:$F$295,KPI_Data!$B$4:$B$295,$B$1,KPI_Data!$C$4:$C$295,"Dock to Stock",KPI_Data!$A$4:$A$295,A16) | D16: =SUMIFS(KPI_Data!$G$4:$G$295,KPI_Data!$B$4:$B$295,$B$1,KPI_Data!$C$4:$C$295,"Dock to Stock",KPI_Data!$A$4:$A$295,A16) | E16: =IFERROR(C16/D16,"") | G16: =EDATE(G15,1) | H16: =INDEX('KPI Schedule'!$B$5:$B$10,MATCH("Cycle Count",'KPI Schedule'!$A$5:$A$10,0)) | I16: =SUMIFS(KPI_Data!$F$4:$F$295,KPI_Data!$B$4:$B$295,$B$1,KPI_Data!$C$4:$C$295,"Cycle Count",KPI_Data!$A$4:$A$295,G16) | J16: =SUMIFS(KPI_Data!$G$4:$G$295,KPI_Data!$B$4:$B$295,$B$1,KPI_Data!$C$4:$C$295,"Cycle Count",KPI_Data!$A$4:$A$295,G16) | K16: =IFERROR(I16/J16,"") | M16: =EDATE(M15,1) | N16: =INDEX('KPI Schedule'!$B$5:$B$10,MATCH("Order Cut Off",'KPI Schedule'!$A$5:$A$10,0)) | O16: =SUMIFS(KPI_Data!$F$4:$F$295,KPI_Data!$B$4:$B$295,$B$1,KPI_Data!$C$4:$C$295,"Order Cut Off",KPI_Data!$A$4:$A$295,M16) | P16: =SUMIFS(KPI_Data!$G$4:$G$295,KPI_Data!$B$4:$B$295,$B$1,KPI_Data!$C$4:$C$295,"Order Cut Off",KPI_Data!$A$4:$A$295,M16) | Q16: =IFERROR(O16/P16,"") | S16: =EDATE(S15,1) | T16: =INDEX('KPI Schedule'!$B$5:$B$10,MATCH("Order Accuracy by Unit",'KPI Schedule'!$A$5:$A$10,0)) | U16: =SUMIFS(KPI_Data!$F$4:$F$295,KPI_Data!$B$4:$B$295,$B$1,KPI_Data!$C$4:$C$295,"Order Accuracy by Unit",KPI_Data!$A$4:$A$295,S16) | V16: =SUMIFS(KPI_Data!$G$4:$G$295,KPI_Data!$B$4:$B$295,$B$1,KPI_Data!$C$4:$C$295,"Order Accuracy by Unit",KPI_Data!$A$4:$A$295,S16) | W16: =IFERROR(U16/V16,"") | Y16: =EDATE(Y15,1) | Z16: =INDEX('KPI Schedule'!$B$5:$B$10,MATCH("Freight DIFOT",'KPI Schedule'!$A$5:$A$10,0)) | AA16: =SUMIFS(KPI_Data!$F$4:$F$295,KPI_Data!$B$4:$B$295,$B$1,KPI_Data!$C$4:$C$295,"Freight DIFOT",KPI_Data!$A$4:$A$295,Y16) | AB16: =SUMIFS(KPI_Data!$G$4:$G$295,KPI_Data!$B$4:$B$295,$B$1,KPI_Data!$C$4:$C$295,"Freight DIFOT",KPI_Data!$A$4:$A$295,Y16) | AC16: =IFERROR(AA16/AB16,"")
A19: Carrier | B19: Target | C19: Numerator | D19: Denominator | E19: Actual %
A20: NZ Couriers | B20: =INDEX('KPI Schedule'!$B$5:$B$10,MATCH("Freight DIFOT",'KPI Schedule'!$A$5:$A$10,0)) | C20: =SUMIFS(KPI_Data!$F$4:$F$295,KPI_Data!$B$4:$B$295,$B$1,KPI_Data!$C$4:$C$295,"Freight DIFOT",KPI_Data!$D$4:$D$295,A20,KPI_Data!$A$4:$A$295,$B$2) | D20: =SUMIFS(KPI_Data!$G$4:$G$295,KPI_Data!$B$4:$B$295,$B$1,KPI_Data!$C$4:$C$295,"Freight DIFOT",KPI_Data!$D$4:$D$295,A20,KPI_Data!$A$4:$A$295,$B$2) | E20: =IFERROR(C20/D20,"")
A21: PBT Transport | B21: =INDEX('KPI Schedule'!$B$5:$B$10,MATCH("Freight DIFOT",'KPI Schedule'!$A$5:$A$10,0)) | C21: =SUMIFS(KPI_Data!$F$4:$F$295,KPI_Data!$B$4:$B$295,$B$1,KPI_Data!$C$4:$C$295,"Freight DIFOT",KPI_Data!$D$4:$D$295,A21,KPI_Data!$A$4:$A$295,$B$2) | D21: =SUMIFS(KPI_Data!$G$4:$G$295,KPI_Data!$B$4:$B$295,$B$1,KPI_Data!$C$4:$C$295,"Freight DIFOT",KPI_Data!$D$4:$D$295,A21,KPI_Data!$A$4:$A$295,$B$2) | E21: =IFERROR(C21/D21,"")
A24: Year | B24: Target | C24: Numerator | D24: Denominator | E24: Actual %
A25: =YEAR($B$2)-1 | B25: =INDEX('KPI Schedule'!$B$5:$B$10,MATCH("Stock Accuracy",'KPI Schedule'!$A$5:$A$10,0)) | C25: =SUMPRODUCT((KPI_Data!$B$4:$B$295=$B$1)*(KPI_Data!$C$4:$C$295="Stock Accuracy")*(YEAR(KPI_Data!$A$4:$A$295)=A25)*KPI_Data!$F$4:$F$295) | D25: =SUMPRODUCT((KPI_Data!$B$4:$B$295=$B$1)*(KPI_Data!$C$4:$C$295="Stock Accuracy")*(YEAR(KPI_Data!$A$4:$A$295)=A25)*KPI_Data!$G$4:$G$295) | E25: =IFERROR(C25/D25,"")
A26: =YEAR($B$2) | B26: =INDEX('KPI Schedule'!$B$5:$B$10,MATCH("Stock Accuracy",'KPI Schedule'!$A$5:$A$10,0)) | C26: =SUMPRODUCT((KPI_Data!$B$4:$B$295=$B$1)*(KPI_Data!$C$4:$C$295="Stock Accuracy")*(YEAR(KPI_Data!$A$4:$A$295)=A26)*KPI_Data!$F$4:$F$295) | D26: =SUMPRODUCT((KPI_Data!$B$4:$B$295=$B$1)*(KPI_Data!$C$4:$C$295="Stock Accuracy")*(YEAR(KPI_Data!$A$4:$A$295)=A26)*KPI_Data!$G$4:$G$295) | E26: =IFERROR(C26/D26,"")
